<?xml version='1.0' ?>

<!-- THIS FILE IS GENERATED FROM acrobot.rsdf -->

<sdf version='1.6'>
  <model name='Acrobot'>

    <link name='link1'>
      <pose>0 0 0.5 0 0 0</pose>
      <inertial>
        <mass>0.1</mass>
        <inertia>
          <ixx>0.03333333333333333</ixx>
          <iyy>0.03333333333333333</iyy>
          <izz>0</izz>
          <ixy>0</ixy><ixz>0</ixz><iyz>0</iyz>
        </inertia>
      </inertial>
      <visual name='link1_vis'>
        <pose>0 0 0 0 0 0</pose>
        <geometry>
          <cylinder>
            <radius>0.04</radius>
            <length>1</length>
          </cylinder>
        </geometry>
      </visual>
    </link>

    <link name='link2'>
      <pose>0 0 0.6 0 0 0</pose>
      <inertial>
        <mass>0.08</mass>
        <inertia>
          <ixx>0.017066666666666667</ixx>
          <iyy>0.017066666666666667</iyy>
          <izz>0</izz>
          <ixy>0</ixy><ixz>0</ixz><iyz>0</iyz>
        </inertia>
      </inertial>
      <visual name='link2_vis'>
        <pose>0 0 0 0 0 0</pose>
        <geometry>
          <cylinder>
            <radius>0.02</radius>
            <length>0.8</length>
          </cylinder>
        </geometry>
      </visual>
    </link>

    <link name='load'>
      <pose>0 0 0.19999999999999996 0 0 0</pose>
      <inertial>
        <inertia>
          <ixx>1.0e-20</ixx><iyy>1.0e-20</iyy><izz>1.0e-20</izz>
          <ixy>0</ixy><ixz>0</ixz><iyz>0</iyz>
        </inertia>
        <mass>0.5</mass>
      </inertial>
      <visual name='load_vis'>
        <pose>0 0 0 0 0 0</pose>
        <geometry>
          <sphere>
            <radius>0.05</radius>
          </sphere>
        </geometry>
      </visual>
    </link>

    <joint name='theta' type='revolute'>
      <parent>world</parent>
      <child>link1</child>
      <pose>0 0 -0.5 0 0 0</pose>
      <axis>
        <xyz>0 1.0 0</xyz>
        <limit>
          <effort>0.0</effort>
        </limit>
      </axis>
    </joint>
        
    <joint name='phi' type='revolute'>
      <parent>link1</parent>
      <child>link2</child>
      <pose>0 0 0.4 0 0 0</pose>
      <axis>
        <xyz>0 1.0 0</xyz>
      </axis>
    </joint>

    <joint name='load_attach' type='fixed'>
      <parent>link2</parent>
      <child>load</child>
      <pose>0 0 0 0 0 0</pose>
    </joint>

  </model>
</sdf>
