<?xml version='1.0' ?>

<!-- THIS FILE IS GENERATED FROM mip.rsdf -->

<sdf version='1.6'>
  <model name='mip'>
    <link name='wheel'>
      <pose>0 0 0 0 0 0</pose>
      <inertial>
        <mass>0.2</mass>
        <inertia>
          <ixx>0.002006666666666667</ixx>
          <iyy>0.004000000000000001</iyy>
          <izz>0.002006666666666667</izz>
          <ixy>0</ixy><ixz>0</ixz><iyz>0</iyz>
        </inertia>
      </inertial>

      <visual name='vis_wheel'>
        <pose>0 0 0 0 0 0</pose>
        <geometry>
          <mesh>
            <uri>torus.obj</uri>
            <scale>0.2 0.2 0.2</scale>
          </mesh>
          <!--<cylinder>-->
            <!--<radius>0.2</radius>-->
            <!--<length>0.02</length>-->
          <!--</cylinder>-->
        </geometry>
      </visual>
      <visual name='vis_wheel2'>
        <pose>0 0 0 1.570795 0 0</pose>
        <geometry>
          <cylinder>
            <radius>0.2</radius>
            <length>0.02</length>
          </cylinder>
        </geometry>
      </visual>
      <collision name='col_wheel'>
        <pose>0 0 0 1.570795 0 0</pose>
        <geometry>
          <!--<mesh>-->
            <!--<uri>torus.obj</uri>-->
          <!--</mesh>-->
          <cylinder>
            <radius>0.2</radius>
            <length>0.02</length>
          </cylinder>
        </geometry>
      </collision>

    </link>

    <link name='pole'>
      <gravity>true</gravity>
      <self_collide>0</self_collide>
      <pose>0 0 0.5 0 0 0</pose>
      <inertial>
        <mass>0.1</mass>
        <inertia>
          <ixx>0.03333333333333333</ixx>
          <iyy>0.03333333333333333</iyy>
          <izz>0</izz>
          <ixy>0</ixy><ixz>0</ixz><iyz>0</iyz>
        </inertia>
      </inertial>

      <visual name='vis_cylinder'>
        <pose>0 0 0 0 0 0</pose>
        <geometry>
          <cylinder>
            <radius>0.04</radius>
            <length>1.0</length>
          </cylinder>
        </geometry>
      </visual>
      <collision name='col_cylinder'>
        <pose>0 0 0 0 0 0</pose>
        <geometry>
          <cylinder>
            <radius>0.04</radius>
            <length>1.0</length>
          </cylinder>
        </geometry>
      </collision>
    </link>

    <link name='load'>
      <pose>0 0 0.5 0 0 0</pose>
      <inertial>
        <mass>0.4</mass>
        <!-- A point mass has zero rotational inertia.
             We must specify small values since otherwise sdformat throws an
             exception. -->
        <inertia>
          <ixx>1.0e-20</ixx><iyy>1.0e-20</iyy><izz>1.0e-20</izz>
          <ixy>0</ixy><ixz>0</ixz><iyz>0</iyz>
        </inertia>
      </inertial>
      <visual name='load_vis'>
        <pose>0 0 0 0 0 0</pose>
        <geometry>
          <sphere>
            <radius>0.05</radius>
          </sphere>
        </geometry>
      </visual>
    </link>

    <link name='x_dummy'>
      <pose>0 0 0 0 0 0</pose>
      <inertial>
        <mass>1e-6</mass>
      </inertial>
    </link>

    <link name='z_dummy'>
      <pose>0 0 0 0 0 0</pose>
      <inertial>
        <mass>1e-6</mass>
      </inertial>
    </link>

    <joint name='z' type='prismatic'>
      <parent>world</parent>
      <child>z_dummy</child>
      <pose>0 0 0 0 0 0</pose>
      <axis>
        <xyz>0 0 1.0</xyz>
        <limit>
          <effort>0.0</effort>
        </limit>
      </axis>
    </joint>

    <joint name='x' type='prismatic'>
      <parent>z_dummy</parent>
      <child>x_dummy</child>
      <pose>0 0 0 0 0 0</pose>
      <axis>
        <xyz>1.0 0 0</xyz>
        <limit>
          <effort>0.0</effort>
        </limit>
      </axis>
    </joint>

    <joint name='theta' type='revolute'>
      <parent>x_dummy</parent>
      <child>pole</child>
      <pose>0 0 -0.5 0 0 0</pose>
      <axis>
        <xyz>0 1.0 0</xyz>
        <limit>
          <effort>0.0</effort>
        </limit>
      </axis>
    </joint>

    <joint name='wheel_pole_joint' type='revolute'>
      <!--With respect to child frame-->
      <pose>0 0 0 0 0 0</pose>
      <parent>pole</parent>
      <child>wheel</child>
      <axis>
        <xyz>0 1.0 0</xyz>
        <!--<use_parent_model_frame>true</use_parent_model_frame>-->
      </axis>
    </joint>

    <joint name='load_fixture' type='fixed'>
      <parent>pole</parent>
      <child>load</child>
      <pose>0 0 0 0 0 0</pose>
    </joint>

  </model>
</sdf>
