<?xml version='1.0' ?>
<sdf version='1.6'>
  <model name='Tribot'>
    <pose>0 0 0.5 0 0 0</pose>
    <link name='wheel'>
      <pose>0 0 0 0 0 0</pose>
      <inertial>
        <mass>10.0</mass>
        <!--TODO: Set correct inertial matrix for wheel -->
        <inertia>
          <ixx>1.0e-20</ixx><iyy>1.0e-20</iyy><izz>1.0e-20</izz>
          <ixy>0</ixy><ixz>0</ixz><iyz>0</iyz>
        </inertia>
      </inertial>

      <visual name='vis_major_wheel_joint'>
        <pose>0 0 0 0 1.5708 0</pose>
        <geometry>
          <cylinder>
            <radius>0.1</radius>
            <length>0.3</length>
          </cylinder>
        </geometry>
      </visual>
      <collision name='col_major_wheel_joint'>
        <pose>0 0 0 0 1.5708 0</pose>
        <geometry>
          <cylinder>
            <radius>0.1</radius>
            <length>0.3</length>
          </cylinder>
        </geometry>
      </collision>

    </link>

    <link name='major_link'>
      <gravity>true</gravity>
      <self_collide>0</self_collide>
      <pose>0 0 0 0 0 0</pose>
      <inertial>
        <pose>0 0 0.5 0 0 0</pose>
        <mass>1.0</mass>
        <!--TODO: Set correct inertial matrix for cylinder -->
      </inertial>

      <visual name='vis_cylinder'>
        <pose>0 0 0.5 0 0 0</pose>
        <geometry>
          <cylinder>
            <radius>0.1</radius>
            <length>1</length>
          </cylinder>
        </geometry>
      </visual>
      <collision name='col_cylinder'>
        <pose>0 0 0.5 0 0 0</pose>
        <geometry>
          <cylinder>
            <radius>0.1</radius>
            <length>1</length>
          </cylinder>
        </geometry>
      </collision>

      <visual name='vis_mid_joint'>
        <pose>0 0 1 0 1.5708 0</pose>
        <geometry>
          <cylinder>
            <radius>0.1</radius>
            <length>0.2</length>
          </cylinder>
        </geometry>
      </visual>
      <collision name='col_mid_joint'>
        <pose>0 0 1 0 1.5708 0</pose>
        <geometry>
          <cylinder>
            <radius>0.1</radius>
            <length>0.2</length>
          </cylinder>
        </geometry>
      </collision>
    </link>

    <link name='minor_link'>
      <gravity>true</gravity>
      <pose>0 0 1 0 0 0</pose>
      <self_collide>0</self_collide>
      <inertial>
        <pose>0 0 0.25 0 0 0</pose>
        <mass>10.0</mass>
        <!--TODO: Set correct inertial matrix for cylinder -->
      </inertial>

      <visual name='vis_cylinder'>
        <pose>0 0 0.25 0 0 0</pose>
        <geometry>
          <cylinder>
            <radius>0.1</radius>
            <length>0.5</length>
          </cylinder>
        </geometry>
      </visual>
      <collision name='col_cylinder'>
        <pose>0 0 0.25 0 0 0</pose>
        <geometry>
          <cylinder>
            <radius>0.1</radius>
            <length>0.5</length>
          </cylinder>
        </geometry>
      </collision>
    </link>

    <joint name='major_link_wheel_joint' type='revolute'>
      <parent>wheel</parent>
      <child>major_link</child>
      <axis>
        <xyz>1.0 0 0</xyz>
        <use_parent_model_frame>true</use_parent_model_frame>
      </axis>
    </joint>

    <joint name='mid_joint' type='revolute'>
      <parent>major_link</parent>
      <child>minor_link</child>
      <axis>
        <xyz>1.0 0 0</xyz>
        <use_parent_model_frame>true</use_parent_model_frame>
      </axis>
    </joint>

  </model>
</sdf>
