<?xml version='1.0' ?>

<!-- THIS FILE IS GENERATED FROM segway.rsdf -->

<sdf version='1.6'>
  <model name='Unibot'>
    <link name='wheel'>
      <pose>0 0 0 0 0 0</pose>
      <inertial>
        <mass>2.0</mass>
        <inertia>
          <ixx>0.02006666666666667</ixx>
          <iyy>0.04000000000000001</iyy>
          <izz>0.02006666666666667</izz>
          <ixy>0</ixy><ixz>0</ixz><iyz>0</iyz>
        </inertia>
      </inertial>

      <visual name='vis_wheel'>
        <pose>0 0 0 1.570795 0 0</pose>
        <geometry>
          <cylinder>
            <radius>0.2</radius>
            <length>0.02</length>
          </cylinder>
        </geometry>
      </visual>
      <collision name='col_wheel'>
        <pose>0 0 0 1.570795 0 0</pose>
        <geometry>
          <cylinder>
            <radius>0.2</radius>
            <length>0.02</length>
          </cylinder>
        </geometry>
      </collision>
    </link>

    <link name='link1'>
      <pose>0 0 0.5 0 0 0</pose>
      <inertial>
        <mass>1.0</mass>
        <inertia>
          <ixx>0.3333333333333333</ixx>
          <iyy>0.3333333333333333</iyy>
          <izz>1e-6</izz>
          <ixy>0</ixy><ixz>0</ixz><iyz>0</iyz>
        </inertia>
      </inertial>
      <visual name='link1_vis'>
        <pose>0 0 0 0 0 0</pose>
        <geometry>
          <cylinder>
            <radius>0.04</radius>
            <length>1</length>
          </cylinder>
        </geometry>
      </visual>
      <collision name='link1_col'>
        <pose>0 0 0 0 0 0</pose>
        <geometry>
          <cylinder>
            <radius>0.04</radius>
            <length>1</length>
          </cylinder>
        </geometry>
      </collision>
    </link>

    <link name='link2'>
      <pose>0 0 0.625 0 0 0</pose>
      <inertial>
        <mass>1.0</mass>
        <inertia>
          <ixx>0.1875</ixx>
          <iyy>0.1875</iyy>
          <izz>1e-6</izz>
          <ixy>0</ixy><ixz>0</ixz><iyz>0</iyz>
        </inertia>
      </inertial>
      <visual name='link2_vis'>
        <pose>0 0 0 0 0 0</pose>
        <geometry>
          <cylinder>
            <radius>0.02</radius>
            <length>0.75</length>
          </cylinder>
        </geometry>
      </visual>
    </link>

    <link name='load'>
      <pose>0 0 0.25 0 0 0</pose>
      <inertial>
        <mass>5.0</mass>
      </inertial>
      <visual name='load_vis'>
        <pose>0 0 0 0 0 0</pose>
        <geometry>
          <sphere>
            <radius>0.05</radius>
          </sphere>
        </geometry>
      </visual>
    </link>

    <link name='x_dummy'>
      <pose>0 0 0 0 0 0</pose>
      <inertial>
        <mass>1e-6</mass>
      </inertial>
    </link>

    <link name='y_dummy'>
      <pose>0 0 0 0 0 0</pose>
      <inertial>
        <mass>1e-6</mass>
      </inertial>
    </link>

    <link name='z_dummy'>
      <pose>0 0 0 0 0 0</pose>
      <inertial>
        <mass>1e-6</mass>
      </inertial>
    </link>

    <link name='roll_dummy'>
      <pose>0 0 0 0 0 0</pose>
      <inertial>
        <mass>1e-6</mass>
      </inertial>
    </link>

    <link name='yaw_dummy'>
      <pose>0 0 0 0 0 0</pose>
      <inertial>
        <mass>1e-6</mass>
      </inertial>
    </link>

    <joint name='z' type='prismatic'>
      <parent>world</parent>
      <child>z_dummy</child>
      <pose>0 0 0 0 0 0</pose>
      <axis>
        <xyz>0 0 1</xyz>
        <limit>
          <effort>0.0</effort>
        </limit>
      </axis>
    </joint>

    <joint name='y' type='prismatic'>
      <parent>z_dummy</parent>
      <child>y_dummy</child>
      <pose>0 0 0 0 0 0</pose>
      <axis>
        <xyz>0 1 0</xyz>
        <limit>
          <effort>0.0</effort>
        </limit>
      </axis>
    </joint>

    <joint name='x' type='prismatic'>
      <parent>y_dummy</parent>
      <child>x_dummy</child>
      <pose>0 0 0 0 0 0</pose>
      <axis>
        <xyz>1 0 0</xyz>
        <limit>
          <effort>0.0</effort>
        </limit>
      </axis>
    </joint>

    <joint name='yaw' type='revolute'>
      <parent>x_dummy</parent>
      <child>yaw_dummy</child>
      <pose>0 0 0 0 0 0</pose>
      <axis>
        <xyz>0 0 1</xyz>
        <limit>
          <effort>0.0</effort>
        </limit>
      </axis>
    </joint>

    <joint name='roll' type='revolute'>
      <parent>yaw_dummy</parent>
      <child>roll_dummy</child>
      <pose>0 0 0 0 0 0</pose>
      <axis>
        <xyz>1 0 0</xyz>
        <limit>
          <effort>0.0</effort>
        </limit>
      </axis>
    </joint>

    <joint name='theta' type='revolute'>
      <parent>roll_dummy</parent>
      <child>link1</child>
      <pose>0 0 -0.5 0 0 0</pose>
      <axis>
        <xyz>0 1.0 0</xyz>
        <limit>
          <effort>0.0</effort>
        </limit>
      </axis>
    </joint>

    <joint name='phi' type='revolute'>
      <parent>link1</parent>
      <child>link2</child>
      <pose>0 0 0.375 0 0 0</pose>
      <axis>
        <xyz>1.0 0 0</xyz>
      </axis>
    </joint>

    <joint name='load_attach' type='fixed'>
      <parent>link2</parent>
      <child>load</child>
      <pose>0 0 0 0 0 0</pose>
    </joint>

    <joint name='wheel_joint' type='revolute'>
      <!--With respect to child frame-->
      <pose>0 0 0 0 0 0</pose>
      <parent>link1</parent>
      <child>wheel</child>
      <axis>
        <xyz>0 1.0 0</xyz>
        <!--<use_parent_model_frame>true</use_parent_model_frame>-->
      </axis>
    </joint>

  </model>
</sdf>

