<?xml version='1.0' ?>

<!-- THIS FILE IS GENERATED FROM wheel.rsdf -->

<sdf version='1.6'>
  <model name='Wheel'>

    <link name='tilt_dummy'>
      <pose>0 0 0 0 0 0</pose>
      <inertial>
        <mass>0.1</mass>
      </inertial>
    </link>
    <link name='turn_dummy'>
      <pose>0 0 0 0 0 0</pose>
      <inertial>
        <mass>0.1</mass>
      </inertial>
    </link>
    <link name='x_dummy'>
      <pose>0 0 0 0 0 0</pose>
      <inertial>
        <mass>0.1</mass>
      </inertial>
    </link>
    <link name='y_dummy'>
      <pose>0 0 0 0 0 0</pose>
      <inertial>
        <mass>0.1</mass>
      </inertial>
    </link>
    <link name='z_dummy'>
      <pose>0 0 0 0 0 0</pose>
      <inertial>
        <mass>0.1</mass>
      </inertial>
    </link>

    <link name='wheel'>
      <pose>0 0 0 0 0 0</pose>
      <inertial>
        <mass>10.0</mass>
        <inertia>
          <ixx>0.10208333333333335</ixx>
          <iyy>0.20000000000000004</iyy>
          <izz>0.10208333333333335</izz>
          <ixy>0</ixy><ixz>0</ixz><iyz>0</iyz>
        </inertia>
      </inertial>

      <visual name='vis_wheel'>
        <pose>0 0 0 0 1.5708 0</pose>
        <geometry>
          <cylinder>
            <radius>0.2</radius>
            <length>0.05</length>
          </cylinder>
        </geometry>
      </visual>
      <collision name='col_wheel'>
        <pose>0 0 0 0 1.5708 0</pose>
        <geometry>
          <cylinder>
            <radius>0.2</radius>
            <length>0.05</length>
          </cylinder>
        </geometry>
      </collision>
    </link>

    <joint name='x' type='prismatic'>
      <pose>0 0 0 0 0 0</pose>
      <parent>world</parent>
      <child>x_dummy</child>
      <axis>
        <xyz>1 0 0</xyz>
        <limit>
          <effort>0.0</effort>
        </limit>
      </axis>
    </joint>

    <joint name='y' type='prismatic'>
      <pose>0 0 0 0 0 0</pose>
      <parent>x_dummy</parent>
      <child>y_dummy</child>
      <axis>
        <xyz>0 1 0</xyz>
        <limit>
          <effort>0.0</effort>
        </limit>
      </axis>
    </joint>

    <joint name='z' type='prismatic'>
      <pose>0 0 0 0 0 0</pose>
      <parent>y_dummy</parent>
      <child>z_dummy</child>
      <axis>
        <xyz>0 0 1</xyz>
        <limit>
          <effort>0.0</effort>
        </limit>
      </axis>
    </joint>

    <joint name='turn' type='revolute'>
      <!--With respect to child frame-->
      <pose>0 0 0 0 0 0</pose>
      <parent>z_dummy</parent>
      <child>turn_dummy</child>
      <axis>
        <xyz>0 0 1</xyz>
        <limit>
          <effort>0.0</effort>
        </limit>
      </axis>
    </joint>

    <joint name='tilt' type='revolute'>
      <!--With respect to child frame-->
      <pose>0 0 0 0 0 0</pose>
      <parent>turn_dummy</parent>
      <child>tilt_dummy</child>
      <axis>
        <xyz>0 1 0</xyz>
        <limit>
          <effort>0.0</effort>
        </limit>
      </axis>
    </joint>

    <joint name='roll' type='revolute'>
      <!--With respect to child frame-->
      <pose>0 0 0 0 0 0</pose>
      <parent>tilt_dummy</parent>
      <child>wheel</child>
      <axis>
        <xyz>1.0 0 0</xyz>
      </axis>
    </joint>

  </model>
</sdf>
